Workbook

Sheet CS
B2: Trữ lượng địa chất | C2: =C3+C4+C5 -> 17198149
B3: Đất tầng phủ | C3: 1720428
B4: Đá phong hóa | C4: 2102668
B5: đá xây dựng | C5: 13375053
B6: Trữ lượng khai thác | C6: =C7+C8+C9 -> 15867229
B7: Đất tầng phủ | C7: 1699156 | D7: =C7+C8 -> 3567853
B8: Đá phong hóa | C8: 1868697
B9: đá xây dựng | C9: 12299376
B12: TT | C12: Năm khai thác | D12: Đơn vị | E12: Khối lượng
E13: Vật liệu san lấp | F13: Đá xây dựng
B14: 1 | C14: Năm thứ 1 (XDCB) | D14: m3 | E14: 1600000 | F14: 3000000
B15: 2 | C15: Năm thứ 2 | D15: m3 | E15: 800000 | F15: 3000000
B16: 3 | C16: Năm thứ 3 | D16: m3 | E16: 800000 | F16: 3000000
B17: 4 | C17: Năm thứ 4 | D17: m3 | E17: 367853 | F17: 3000000
B18: 5 | C18: Năm thứ 5 | D18: m3 | F18: 299376
B19: Tổng | D19: m3 | E19: =SUM(E14:E18) -> 3567853 | F19: =SUM(F14:F18) -> 12299376

Sheet TB
A3: STT | B3: Thiết bị | C3: ĐVT | D3: Số lượng | E3: Đơn giá | F3: Giá trị trước thuế | G3: Thuế VAT | H3: Giá trị sau thuế
A4: I | B4: THIẾT BỊ KHAI THÁC | F4: =SUM(F5:F15) -> 123527000000 | G4: =SUM(G5:G15) -> 12352700000 | H4: =SUM(H5:H15) -> 135879700000
A5: 1 | B5: Tổ hợp nghiền sàng 350 tấn/h | C5: Trạm | D5: =D37 -> 5 | E5: 11000000000 | F5: =D5*E5 -> 55000000000 | G5: =F5*10% -> 5500000000 | H5: =F5+G5 -> 60500000000
A6: 4 | B6: Trạm biến áp | C6: Trạm | D6: 4 | E6: 1500000000 | F6: =D6*E6 -> 6000000000 | G6: =F6*10% -> 600000000 | H6: =F6+G6 -> 6600000000
A7: 5 | B7: Máy xúc thủy lực | C7: Chiếc | D7: 16 | E7: 1200000000 | F7: =D7*E7 -> 19200000000 | G7: =F7*10% -> 1920000000 | H7: =F7+G7 -> 21120000000
A8: 6 | B8: Ô tô 15 tấn | C8: Chiếc | D8: =D40 -> 50 | E8: 630000000 | F8: =D8*E8 -> 31500000000 | G8: =F8*10% -> 3150000000 | H8: =F8+G8 -> 34650000000
A9: 7 | B9: Búa đập thủy lực | C9: Chiếc | D9: =D41 -> 3 | E9: 500000000 | F9: =D9*E9 -> 1500000000 | G9: =F9*10% -> 150000000 | H9: =F9+G9 -> 1650000000
A10: 8 | B10: Máy xúc lật | C10: Chiếc | D10: =D42 -> 6 | E10: 1200000000 | F10: =D10*E10 -> 7200000000 | G10: =F10*10% -> 720000000 | H10: =F10+G10 -> 7920000000
A11: 9 | B11: Máy khoan BMK-5 | C11: Chiếc | D11: =D43 -> 3 | E11: 120000000 | F11: =D11*E11 -> 360000000 | G11: =F11*10% -> 36000000 | H11: =F11+G11 -> 396000000
A12: 10 | B12: Búa khoan tay | C12: Chiếc | D12: =D44 -> 9 | E12: 3000000 | F12: =D12*E12 -> 27000000 | G12: =F12*10% -> 2700000 | H12: =F12+G12 -> 29700000
A13: 11 | B13: Máy nén khí | C13: HT | D13: =D45 -> 4 | E13: 120000000 | F13: =D13*E13 -> 480000000 | G13: =F13*10% -> 48000000 | H13: =F13+G13 -> 528000000
A14: 12 | B14: Xe bồn tưới nước | C14: Chiếc | D14: =D46 -> 2 | E14: 850000000 | F14: =D14*E14 -> 1700000000 | G14: =F14*10% -> 170000000 | H14: =F14+G14 -> 1870000000
A15: 14 | B15: Xe công vụ | C15: Chiếc | D15: =D47 -> 1 | E15: 560000000 | F15: =D15*E15 -> 560000000 | G15: =F15*10% -> 56000000 | H15: =F15+G15 -> 616000000
A16: II | B16: THIẾT BỊ VĂN PHÒNG | F16: =SUM(F17:F31) -> 89700000 | G16: =SUM(G17:G31) -> 8970000 | H16: =SUM(H17:H31) -> 98670000
A17: 15 | B17: Điện thoại di động | C17: cái | D17: 4 | E17: 4000000 | F17: =D17*E17 -> 16000000 | G17: =F17*10% -> 1600000 | H17: =F17+G17 -> 17600000
A18: 16 | B18: Điện thoại bàn | C18: cái | D18: 4 | E18: 500000 | F18: =D18*E18 -> 2000000 | G18: =F18*10% -> 200000 | H18: =F18+G18 -> 2200000
A19: 17 | B19: Bàn ghế nhà ăn | C19: bộ | D19: 2 | E19: 3000000 | F19: =D19*E19 -> 6000000 | G19: =F19*10% -> 600000 | H19: =F19+G19 -> 6600000
A20: 18 | B20: Bàn ghế làm việc | C20: bộ | D20: 4 | E20: 2000000 | F20: =D20*E20 -> 8000000 | G20: =F20*10% -> 800000 | H20: =F20+G20 -> 8800000
A21: 19 | B21: Quạt điện đứng | C21: cái | D21: 5 | E21: 250000 | F21: =D21*E21 -> 1250000 | G21: =F21*10% -> 125000 | H21: =F21+G21 -> 1375000
A22: 20 | B22: Máy tính | C22: bộ | D22: 5 | E22: 6000000 | F22: =D22*E22 -> 30000000 | G22: =F22*10% -> 3000000 | H22: =F22+G22 -> 33000000
A23: 21 | B23: Máy fax | C23: cái | D23: 1 | E23: 4000000 | F23: =D23*E23 -> 4000000 | G23: =F23*10% -> 400000 | H23: =F23+G23 -> 4400000
A24: 22 | B24: Máy in | C24: cái | D24: 1 | E24: 3500000 | F24: =D24*E24 -> 3500000 | G24: =F24*10% -> 350000 | H24: =F24+G24 -> 3850000
A25: 23 | B25: Máy lạnh | C25: cái | D25: 1 | E25: 6500000 | F25: =D25*E25 -> 6500000 | G25: =F25*10% -> 650000 | H25: =F25+G25 -> 7150000
A26: 24 | B26: Máy tính tay Casio | C26: cái | D26: 5 | E26: 200000 | F26: =D26*E26 -> 1000000 | G26: =F26*10% -> 100000 | H26: =F26+G26 -> 1100000
A27: 25 | B27: Tủ đựng hồ sơ | C27: cái | D27: 4 | E27: 1000000 | F27: =D27*E27 -> 4000000 | G27: =F27*10% -> 400000 | H27: =F27+G27 -> 4400000
A28: 26 | B28: Bình chữa cháy | C28: cái | D28: 3 | E28: 500000 | F28: =D28*E28 -> 1500000 | G28: =F28*10% -> 150000 | H28: =F28+G28 -> 1650000
... A31: 29 | B31: Các thiết bị khác | C31: bộ | D31: 1 | E31: 5000000 | F31: =D31*E31 -> 5000000 | G31: =F31*10% -> 500000 | H31: =F31+G31 -> 5500000
B32: Tổng cộng | F32: =F16+F4 -> 123616700000 | G32: =G16+G4 -> 12361670000 | H32: =H16+H4 -> 135978370000
A36: I | B36: THIẾT BỊ KHAI THÁC | E36: Nhu cầu | G36: Công suất | H36: Số lượng
A37: 2 | B37: Tổ hợp nghiền sàng 350 tấn/h | C37: Trạm | D37: 5 | E37: 1562.5 | F37: tấn/h | G37: 350
A38: 4 | B38: Trạm biến áp | C38: Trạm | D38: 4
A39: 5 | B39: Máy xúc thủy lực | C39: Chiếc | D39: 16 | G39: 2.5
A40: 6 | B40: Ô tô 15 tấn | C40: Chiếc | D40: 50
A41: 7 | B41: Búa đập thủy lực | C41: Chiếc | D41: 3
A42: 8 | B42: Máy xúc lật | C42: Chiếc | D42: 6
A43: 9 | B43: Máy khoan BMK-5 | C43: Chiếc | D43: 3
A44: 10 | B44: Búa khoan tay | C44: Chiếc | D44: 9
A45: 11 | B45: Máy nén khí | C45: HT | D45: 4
A46: 12 | B46: Xe bồn tưới nước | C46: Chiếc | D46: 2
A47: 14 | B47: Xe công vụ | C47: Chiếc | D47: 1
...

Sheet XDCB
A1: TỔNG HỢP CHI PHÍ XÂY DỰNG CÔNG TRÌNH
H2: ĐVT: đồng
A3: TT | B3: HẠNG MỤC | C3: Đơn vị | D3: Khối lượng | E3: Giá trị trước thuế | F3: Thuế GTGT | G3: Giá trị sau thuế | H3: Ghi chú
A4: A | B4: PHẦN XÂY DỰNG CƠ BẢN | E4: =SUM(E5:E8) -> 6056430000 | F4: =SUM(F5:F8) -> 605643000 | G4: =SUM(G5:G8) -> 6662073000
A5: 1 | B5: Thi công tuyến đường vận tải, duy tu cải tạo | C5: m3 | D5: =12900*0.3 -> 3870 | E5: =D5*200000 -> 774000000 | F5: =E5*0.1 -> 77400000 | G5: =E5+F5 -> 851400000 | J5: 4.7524044e+09
A6: 2 | B6: Thi công san nền khu phụ trợ | C6: m2 | D6: =65686 -> 65686 | E6: =500000000*D6/100000 -> 328430000 | F6: =E6*0.1 -> 32843000 | G6: =E6+F6 -> 361273000
A7: 3 | B7: Thi công diện khai thác đầu tiên | C7: m3 | D7: 4554 | E7: =D7*1000000 -> 4554000000 | F7: =E7*0.1 -> 455400000 | G7: =E7+F7 -> 5009400000
A8: 4 | B8: Chi phí xây dựng hồ lắng nước, hố thu nước | C8: m3 | D8: 4000 | E8: =D8*100000 -> 400000000 | F8: =E8*0.1 -> 40000000 | G8: =E8+F8 -> 440000000
A9: B | B9: KHU PHỤ TRỢ MỎ | E9: =SUM(E10:E17) -> 2045000000 | F9: =SUM(F10:F17) -> 204500000 | G9: =SUM(G10:G17) -> 2249500000
A10: 1 | B10: Nhà văn phòng | C10: m2 | D10: 270 | E10: =D10*500000 -> 135000000 | F10: =E10*0.1 -> 13500000 | G10: =E10+F10 -> 148500000
A11: 2 | B11: Nhà nghỉ công nhân, nhà ăn, nhà vệ sinh | C11: m2 | D11: 230 | E11: =D11*500000 -> 115000000 | F11: =E11*0.1 -> 11500000 | G11: =E11+F11 -> 126500000
A12: 3 | B12: Kho vật tư | C12: m2 | D12: 70 | E12: =D12*500000 -> 35000000 | F12: =E12*0.1 -> 3500000 | G12: =E12+F12 -> 38500000
A13: 4 | B13: Xưởng sửa chữa thiết bị | C13: m2 | D13: 60 | E13: =D13*500000 -> 30000000 | F13: =E13*0.1 -> 3000000 | G13: =E13+F13 -> 33000000
A14: 5 | B14: Kho chất thải nguy hại | C14: m2 | D14: 50 | E14: =D14*500000 -> 25000000 | F14: =E14*0.1 -> 2500000 | G14: =E14+F14 -> 27500000
A15: 6 | B15: Kho nhiên liệu | C15: m2 | D15: 200 | E15: =D15*500000 -> 100000000 | F15: =E15*0.1 -> 10000000 | G15: =E15+F15 -> 110000000
A16: 7 | B16: Nhà bảo vệ | C16: m2 | D16: 10 | E16: =D16*500000 -> 5000000 | F16: =E16*0.1 -> 500000 | G16: =E16+F16 -> 5500000
A17: 8 | B17: Trạm điện 1000KVA | C17: Trạm | D17: 2 | E17: =D17*800000000 -> 1600000000 | F17: =E17*0.1 -> 160000000 | G17: =E17+F17 -> 1760000000
B18: TỔNG CHI PHÍ XÂY DỰNG | E18: =E4+E9 -> 8101430000 | F18: =F4+F9 -> 810143000 | G18: =G4+G9 -> 8911573000
A19: II | B19: Khu phô trî | E19: =SUM(E5:E5) -> 774000000
B20: HÖ thèng cÊp ®iÖn
B21: HÖ thèng cÊp n­íc
A22: II | B22: Chi phÝ x©y nhµ t¹m t¹i hiÖn tr­êng ®Ó ë vµ ®iÒu hµnh thi c«ng
A23: III | B23: Tæng møc ®Çu t­ x©y dùng c¬ b¶n | E23: =#REF!+E22+E19+E20+E21 -> #REF! | F23: =#REF!+F22+F19+F20+F21 -> #REF! | G23: =#REF!+G22+G19+G20+G21 -> #REF!
E25: ='[1]6,CFSX'!#REF!*80000/1.1 -> #REF! | F25: =E25*0.1 -> #REF! | G25: =E25+F25 -> #REF!
E27: =E18-E25 -> #REF! | F27: =F18-F25 -> #REF! | G27: =G18-G25 -> #REF!
B32: 3069867120
B33: 4052433770 | E33: 2101576600 | G33: 66084857773
B34: =B35-E35 -> 2125199110 | E34: 2895525180 | H34: =#REF!-F39 -> #REF! | I34: =H34/1.1 -> #REF!
B35: 7122300890 | E35: =SUM(E33:E34) -> 4997101780 | G35: =G18-G33 -> -57173284773
B36: =B32+B33 -> 7122300890 | H36: ='[1]1-Tong Muc DT (2)'!#REF!/1.1 -> #REF! | I36: =#REF!-H36 -> #REF!
B37: 5.5275647e+10 | E37: 5.5275647e+09 | F37: 6.0803212e+10 | G37: 66085011000
B38: =B37-E18 -> 4.7174217e+10
B39: =B38+#REF! -> #REF! | E39: =#REF!+F39 -> #REF! | F39: ='[1]1-Tong Muc DT (2)'!#REF! -> #REF! | G39: =#REF!-'[1]1-Tong Muc DT (2)'!#REF! -> #REF! | H39: =G39/1.1 -> #REF!
F41: =28+5 -> 33 | G41: =E39/1.1 -> #REF!
E42: =F39/1.1 -> #REF! | F42: =E42*1.1 -> #REF!
F45: =554059/13.64 -> 40620.161 | G45: =F45*0.05 -> 2031.0081
E47: =#REF! -> #REF!
E48: 9051818382

Sheet KHAC
A2: STT | B2: Nội dung | C2: ĐMTL | D2: Cách tính | E2: Trước thuế | F2: VAT | G2: Sau thuế
A3: 1 | B3: Chi phí xây dựng nhà tạm tại hiện trường để ở và điều hành thi công | C3: 0.011 | D3: ĐMTL*GXD | E3: =XDCB!E18*1.1% -> 89115730 | F3: =E3*10% -> 8911573 | G3: =E3+F3 -> 98027303
A4: 2 | B4: Chi phí một số công tác không xác định được khối lượng từ thiết kế | C4: 0.02 | D4: ĐMTL*GTB | E4: =XDCB!E18*2% -> 162028600 | F4: =E4*10% -> 16202860 | G4: =E4+F4 -> 178231460
A5: 3 | B5: Vốn lưu động ban đầu cho sản xuất | E5: 100000000 | F5: 0 | G5: =E5+F5 -> 100000000
B6: Tổng cộng: | E6: =SUM(E3:E5) -> 351144330 | F6: =SUM(F3:F5) -> 25114433 | G6: =SUM(G3:G5) -> 376258763

Sheet QLDA
B2: STT | C2: Mục chi phí | D2: Giá trị trước thuế | E2: Thuế VAT | F2: Giá trị sau thuế
B3: 1 | C3: Chi phí thăm dò khoáng sản | D3: 10000000000 | E3: =D3*10% -> 1000000000 | F3: =D3+E3 -> 11000000000
B4: 2 | C4: Chi phí lập Báo cáo nghiên cứu khả thi (điều chỉnh), trình thẩm định | D4: 600000000 | E4: =D4*10% -> 60000000 | F4: =D4+E4 -> 660000000
B5: 3 | C5: Chi phí lập ĐTM và trình duyệt | D5: 1000000000 | E5: =D5*10% -> 100000000 | F5: =D5+E5 -> 1100000000
B6: 4 | C6: Chi phí tư vấn khác | D6: 2000000000 | E6: =D6*10% -> 200000000 | F6: =D6+E6 -> 2200000000
C7: Tổng cộng | D7: =D6+D5+D4+D3 -> 13600000000 | E7: =D7*10% -> 1360000000 | F7: =D7+E7 -> 14960000000
B10: STT | C10: Các khoản chi phí | D10: Diễn giải | E10: Giá trị | F10: Thuế VAT | G10: Giá trị sau thuế
E11: trước thuế
B12: I | C12: Chi chí quản lý dự án theo quy định | D12: (Gxd+Gtb) x 3,557% | E12: =(TB!F32+XDCB!E18)*3.557% -> 4.6852139e+09 | F12: =E12*10% -> 4.6852139e+08 | G12: =E12+F12 -> 5.1537353e+09
B13: II | C13: Chi phí khác | E13: =SUM(E14:E21) -> 2.3889788e+10 | F13: =E13*10% -> 2.3889788e+09 | G13: =E13+F13 -> 2.6278767e+10
B14: 1 | C14: Lắp đặt trạm cân, camera để xác định, giám sát sản lượng khoáng sản khai thác thực tế. | D14: TT | E14: 2000000000 | F14: =E14*10% -> 200000000 | G14: =E14+F14 -> 2200000000
B15: 2 | C15: Các loại thuế, phí
B16: - | C16: Lệ phí cấp phép khai thác khoáng sản | E16: 50000000 | G16: =E16+F16 -> 50000000
B17: - | C17: Phí thẩm định phương án khai thác | D17: Gxd x 0,188% | E17: =XDCB!E18*0.188% -> 15230688 | F17: =E17*10% -> 1523068.8 | G17: =E17+F17 -> 16753757
B18: 3 | C18: Chi phí thẩm tra, phê duyệt quyết toán | D18: (Gxd+Gtb) x 0,495% | E18: =(TB!F32+XDCB!E18)*0.495% -> 6.5200474e+08 | F18: =E18*10% -> 65200474 | G18: =E18+F18 -> 7.1720522e+08
B19: 4 | C19: Chi phí kiểm toán độc lập | D19: (Gxd+Gtb) x 0,785% | E19: =(TB!F32+XDCB!E18)*0.785% -> 1.0339873e+09 | F19: =E19*10% -> 1.0339873e+08 | G19: =E19+F19 -> 1.1373861e+09
B20: 5 | C20: Tiền cấp quyền khai thác KS năm đầu | D20: Nghị định số 193/2025/NĐ- CP ngày 02/7/2025 | E20: =thuế!L32 -> 18138565466 | G20: =E20+F20 -> 18138565466
B21: 6 | C21: Ký quỹ cải tạo phục hồi môi trường năm đầu | E21: 2000000000 | G21: =E21+F21 -> 2000000000
C22: TỔNG CỘNG | E22: =E13+E12 -> 2.8575002e+10 | F22: =F13+F12 -> 2.8575002e+09 | G22: =G13+G12 -> 3.1432502e+10

Sheet dự phòng
A2: STT | B2: Hạng mục | C2: Giá trị
A3: 1 | B3: Chi phí xây dựng (GXD): | C3: =XDCB!E18 -> 8101430000
A4: 2 | B4: Chi phí thiết bị (GTB): | C4: =TB!F32 -> 123616700000
A5: 3 | B5: Chi phí quản lý dự án (GQLDA): | C5: =QLDA!E12 -> 4.6852139e+09
A6: 4 | B6: Chi phí tư vấn đầu tư xây dựng (GTV): | C6: =QLDA!D7 -> 13600000000
A7: 5 | B7: Chi phí khác (GK): | C7: =QLDA!E13 -> 2.3889788e+10
A8: 6 | B8: Hệ số phát sinh Kps (%) | C8: 10
A9: 7 | B9: Dự phòng cho khối lượng phát sinh (GDP1) | C9: =SUM(C3:C7)*C8% -> 1.7389313e+10
A10: 8 | B10: Dự phòng cho yếu tố trượt giá (GDP2) | C10: 0
A11: 9 | B11: Tổng chi phí dự phòng GDP | C11: =C10+C9 -> 1.7389313e+10

Sheet tổng mức
B2: STT | C2: NỘI DUNG CHI PHÍ | D2: GIÁ TRỊ TRƯỚC THUẾ | E2: THUẾ GTGT | F2: GIÁ TRỊ SAU THUẾ | G2: KÝ HIỆU
B3: 1 | C3: Chi phí xây dựng | D3: ='dự phòng'!C3 -> 8101430000 | E3: =D3*10% -> 810143000 | F3: =D3+E3 -> 8911573000 | G3: GXD
B4: 2 | C4: Chi phí thiết bị | D4: ='dự phòng'!C4 -> 123616700000 | E4: =D4*10% -> 12361670000 | F4: =D4+E4 -> 135978370000 | G4: GTB
B5: 3 | C5: Chi phí quản lý dự án | D5: ='dự phòng'!C5 -> 4.6852139e+09 | E5: =D5*10% -> 4.6852139e+08 | F5: =D5+E5 -> 5.1537353e+09 | G5: GQLDA
B6: 4 | C6: Chi phí tư vấn đầu tư xây dựng | D6: ='dự phòng'!C6 -> 13600000000 | E6: =D6*10% -> 1360000000 | F6: =D6+E6 -> 14960000000 | G6: GTV
B7: 5 | C7: Chi phí khác | D7: ='dự phòng'!C7 -> 2.3889788e+10 | E7: =D7*10% -> 2.3889788e+09 | F7: =D7+E7 -> 2.6278767e+10 | G7: GK
B8: 6 | C8: Chi phí dự phòng (GDP1 + GDP2) | D8: ='dự phòng'!C11 -> 1.7389313e+10 | E8: =D8*10% -> 1.7389313e+09 | F8: =D8+E8 -> 1.9128245e+10 | G8: GDP
B9: 7 | C9: Chi phí giải phóng mặt bằng | D9: =F14 -> 46720000000 | E9: 0 | F9: =D9 -> 46720000000 | G9: GGPMB
B10: Tổng cộng: | D10: =SUM(D3:D9) -> 2.3800245e+11 | E10: =SUM(E3:E9) -> 1.9128245e+10 | F10: =ROUND((D10+E10),-3) -> 257130690000 | G10: GTMĐT
C14: Diện tích | D14: 23.36 | E14: 2000000000 | F14: =D14*E14 -> 46720000000

Sheet thuế
F2: STT | G2: Hạng mục | H2: Giá trị
H3: Đá xây dựng | I3: vật liệu san lấp
F4: 1 | G4: Trữ lượng nguyên khối (m3) | H4: =CS!F19 -> 12299376 | I4: =CS!E19 -> 3567853
F5: 2 | G5: Trữ lượng nguyên khai (m3) | H5: =H4*1.475 -> 18141580 | I5: =I4*1.26 -> 4495494.8
F6: 3 | G6: Đơn giá tính thuế (đồng/m3) | H6: 119000 | I6: 75000
F7: 4 | G7: Thuế suất | H7: 0.15 | I7: =H7 -> 0.15
F8: 5 | G8: Tổng (đồng) | H8: =H7*H6*H5 -> 323827195860 | I8: =I7*I6*I5 -> 50574316275
F9: 6 | G9: Tổng (đồng) | H9: =H8+I8 -> 374401512135
F10: 7 | G10: Tuổi thọ mỏ | H10: 4.5
F11: 8 | G11: Năm 1 - 4 | H11: =H9/H10 -> 83200336030
F12: 9 | G12: Năm 5 | H12: =H9-H11*4 -> 41600168015
F15: STT | G15: Hạng mục | H15: Giá trị
H16: Đá xây dựng | I16: vật liệu san lấp
F17: 1 | G17: Trữ lượng nguyên khối (m3) | H17: =H4 -> 12299376 | I17: =I4 -> 3567853
F18: 2 | G18: Trữ lượng nguyên khai (m3) | H18: =H17*1.475 -> 18141580 | I18: =I17*1.26 -> 4495494.8
F19: 3 | G19: Đơn giá tính thuế (đồng/m3) | H19: 6000 | I19: 2000
F20: 4 | G20: Công nghệ khai thác (lộ thiên) | H20: 1.1 | I20: 1.1
F21: 5 | G21: Tổng (đồng) | H21: =H20*H19*H18 -> 1.1973443e+11 | I21: =I20*I19*I18 -> 9890088516
F22: 6 | G22: Tổng (đồng) | H22: =H21+I21 -> 1.2962451e+11
F23: 7 | G23: Tuổi thọ mỏ | H23: 4.5
F24: 8 | G24: Năm 1 - 4 | H24: =H22/H23 -> 2.8805448e+10
F25: 9 | G25: Năm 5 | H25: =H22-H24*4 -> 14402723764
F28: 1 | G28: Phí cấp quyền khai thác khoáng sản | L28: =L29+L30 -> 81623544597
G29: Đá xây dựng | H29: m3 | I29: 119000 | J29: =CS!F19 -> 12299376 | K29: 0.03 | L29: =I29*J29*K29*1.475 -> 6.4765439e+10
G30: Đất san lấp | H30: m3 | I30: 75000 | J30: =CS!E19 -> 3567853 | K30: 0.05 | L30: =I30*J30*K30*1.26 -> 16858105425
L32: =L28/4.5 -> 18138565466
